[2025-09-07T20:38:39.056+0000] {local_task_job_runner.py:120} INFO - ::group::Pre task execution logs
[2025-09-07T20:38:39.092+0000] {taskinstance.py:2076} INFO - Dependencies all met for dep_context=non-requeueable deps ti=<TaskInstance: train_model_dag_batch_iterative_85000.train_model_iterative manual__2025-09-07T20:37:53.450997+00:00 [queued]>
[2025-09-07T20:38:39.112+0000] {taskinstance.py:2076} INFO - Dependencies all met for dep_context=requeueable deps ti=<TaskInstance: train_model_dag_batch_iterative_85000.train_model_iterative manual__2025-09-07T20:37:53.450997+00:00 [queued]>
[2025-09-07T20:38:39.113+0000] {taskinstance.py:2306} INFO - Starting attempt 1 of 2
[2025-09-07T20:38:39.157+0000] {taskinstance.py:2330} INFO - Executing <Task(PythonOperator): train_model_iterative> on 2025-09-07 20:37:53.450997+00:00
[2025-09-07T20:38:39.174+0000] {standard_task_runner.py:63} INFO - Started process 5528 to run task
[2025-09-07T20:38:39.180+0000] {standard_task_runner.py:90} INFO - Running: ['airflow', 'tasks', 'run', 'train_model_dag_batch_iterative_85000', 'train_model_iterative', 'manual__2025-09-07T20:37:53.450997+00:00', '--job-id', '366', '--raw', '--subdir', 'DAGS_FOLDER/train_dag.py', '--cfg-path', '/tmp/tmpxfutcg4l']
[2025-09-07T20:38:39.184+0000] {standard_task_runner.py:91} INFO - Job 366: Subtask train_model_iterative
[2025-09-07T20:38:39.282+0000] {task_command.py:426} INFO - Running <TaskInstance: train_model_dag_batch_iterative_85000.train_model_iterative manual__2025-09-07T20:37:53.450997+00:00 [running]> on host 31d1c5cf642c
[2025-09-07T20:38:39.551+0000] {taskinstance.py:2648} INFO - Exporting env vars: AIRFLOW_CTX_DAG_OWNER='airflow' AIRFLOW_CTX_DAG_ID='train_model_dag_batch_iterative_85000' AIRFLOW_CTX_TASK_ID='train_model_iterative' AIRFLOW_CTX_EXECUTION_DATE='2025-09-07T20:37:53.450997+00:00' AIRFLOW_CTX_TRY_NUMBER='1' AIRFLOW_CTX_DAG_RUN_ID='manual__2025-09-07T20:37:53.450997+00:00'
[2025-09-07T20:38:39.554+0000] {taskinstance.py:430} INFO - ::endgroup::
[2025-09-07T20:49:08.750+0000] {taskinstance.py:441} INFO - ::group::Post task execution logs
[2025-09-07T20:49:08.767+0000] {taskinstance.py:2905} ERROR - Task failed with exception
Traceback (most recent call last):
  File "/home/airflow/.local/lib/python3.8/site-packages/urllib3/connectionpool.py", line 467, in _make_request
    six.raise_from(e, None)
  File "<string>", line 3, in raise_from
  File "/home/airflow/.local/lib/python3.8/site-packages/urllib3/connectionpool.py", line 462, in _make_request
    httplib_response = conn.getresponse()
  File "/usr/local/lib/python3.8/http/client.py", line 1348, in getresponse
    response.begin()
  File "/usr/local/lib/python3.8/http/client.py", line 316, in begin
    version, status, reason = self._read_status()
  File "/usr/local/lib/python3.8/http/client.py", line 277, in _read_status
    line = str(self.fp.readline(_MAXLINE + 1), "iso-8859-1")
  File "/usr/local/lib/python3.8/socket.py", line 669, in readinto
    return self._sock.recv_into(b)
socket.timeout: timed out

During handling of the above exception, another exception occurred:

Traceback (most recent call last):
  File "/home/airflow/.local/lib/python3.8/site-packages/requests/adapters.py", line 667, in send
    resp = conn.urlopen(
  File "/home/airflow/.local/lib/python3.8/site-packages/urllib3/connectionpool.py", line 799, in urlopen
    retries = retries.increment(
  File "/home/airflow/.local/lib/python3.8/site-packages/urllib3/util/retry.py", line 550, in increment
    raise six.reraise(type(error), error, _stacktrace)
  File "/home/airflow/.local/lib/python3.8/site-packages/urllib3/packages/six.py", line 770, in reraise
    raise value
  File "/home/airflow/.local/lib/python3.8/site-packages/urllib3/connectionpool.py", line 715, in urlopen
    httplib_response = self._make_request(
  File "/home/airflow/.local/lib/python3.8/site-packages/urllib3/connectionpool.py", line 469, in _make_request
    self._raise_timeout(err=e, url=url, timeout_value=read_timeout)
  File "/home/airflow/.local/lib/python3.8/site-packages/urllib3/connectionpool.py", line 358, in _raise_timeout
    raise ReadTimeoutError(
urllib3.exceptions.ReadTimeoutError: HTTPConnectionPool(host='train-api', port=5002): Read timed out. (read timeout=600)

During handling of the above exception, another exception occurred:

Traceback (most recent call last):
  File "/home/airflow/.local/lib/python3.8/site-packages/airflow/models/taskinstance.py", line 465, in _execute_task
    result = _execute_callable(context=context, **execute_callable_kwargs)
  File "/home/airflow/.local/lib/python3.8/site-packages/airflow/models/taskinstance.py", line 432, in _execute_callable
    return execute_callable(context=context, **execute_callable_kwargs)
  File "/home/airflow/.local/lib/python3.8/site-packages/airflow/models/baseoperator.py", line 401, in wrapper
    return func(self, *args, **kwargs)
  File "/home/airflow/.local/lib/python3.8/site-packages/airflow/operators/python.py", line 235, in execute
    return_value = self.execute_callable()
  File "/home/airflow/.local/lib/python3.8/site-packages/airflow/operators/python.py", line 252, in execute_callable
    return self.python_callable(*self.op_args, **self.op_kwargs)
  File "/opt/airflow/dags/train_dag.py", line 95, in send_batches_to_train_api
    response = requests.post(train_url, headers=headers, data=json.dumps(payload), timeout=600)
  File "/home/airflow/.local/lib/python3.8/site-packages/requests/api.py", line 115, in post
    return request("post", url, data=data, json=json, **kwargs)
  File "/home/airflow/.local/lib/python3.8/site-packages/requests/api.py", line 59, in request
    return session.request(method=method, url=url, **kwargs)
  File "/home/airflow/.local/lib/python3.8/site-packages/requests/sessions.py", line 589, in request
    resp = self.send(prep, **send_kwargs)
  File "/home/airflow/.local/lib/python3.8/site-packages/requests/sessions.py", line 703, in send
    r = adapter.send(request, **kwargs)
  File "/home/airflow/.local/lib/python3.8/site-packages/requests/adapters.py", line 713, in send
    raise ReadTimeout(e, request=request)
requests.exceptions.ReadTimeout: HTTPConnectionPool(host='train-api', port=5002): Read timed out. (read timeout=600)
[2025-09-07T20:49:08.858+0000] {taskinstance.py:1206} INFO - Marking task as UP_FOR_RETRY. dag_id=train_model_dag_batch_iterative_85000, task_id=train_model_iterative, run_id=manual__2025-09-07T20:37:53.450997+00:00, execution_date=20250907T203753, start_date=20250907T203839, end_date=20250907T204908
[2025-09-07T20:49:08.938+0000] {standard_task_runner.py:110} ERROR - Failed to execute job 366 for task train_model_iterative (HTTPConnectionPool(host='train-api', port=5002): Read timed out. (read timeout=600); 5528)
[2025-09-07T20:49:09.051+0000] {local_task_job_runner.py:240} INFO - Task exited with return code 1
[2025-09-07T20:49:09.160+0000] {taskinstance.py:3503} INFO - 0 downstream tasks scheduled from follow-on schedule check
[2025-09-07T20:49:09.182+0000] {local_task_job_runner.py:222} INFO - ::endgroup::
