[2025-09-08T19:22:35.513+0000] {local_task_job_runner.py:120} INFO - ::group::Pre task execution logs
[2025-09-08T19:22:35.587+0000] {taskinstance.py:2076} INFO - Dependencies all met for dep_context=non-requeueable deps ti=<TaskInstance: train_model_dag_batch_iterative_85000.train_model_iterative manual__2025-09-08T19:09:15.653145+00:00 [queued]>
[2025-09-08T19:22:35.614+0000] {taskinstance.py:2076} INFO - Dependencies all met for dep_context=requeueable deps ti=<TaskInstance: train_model_dag_batch_iterative_85000.train_model_iterative manual__2025-09-08T19:09:15.653145+00:00 [queued]>
[2025-09-08T19:22:35.616+0000] {taskinstance.py:2306} INFO - Starting attempt 2 of 2
[2025-09-08T19:22:35.675+0000] {taskinstance.py:2330} INFO - Executing <Task(PythonOperator): train_model_iterative> on 2025-09-08 19:09:15.653145+00:00
[2025-09-08T19:22:35.700+0000] {standard_task_runner.py:63} INFO - Started process 7322 to run task
[2025-09-08T19:22:35.712+0000] {standard_task_runner.py:90} INFO - Running: ['airflow', 'tasks', 'run', 'train_model_dag_batch_iterative_85000', 'train_model_iterative', 'manual__2025-09-08T19:09:15.653145+00:00', '--job-id', '404', '--raw', '--subdir', 'DAGS_FOLDER/train_dag.py', '--cfg-path', '/tmp/tmpdc1tprzk']
[2025-09-08T19:22:35.717+0000] {standard_task_runner.py:91} INFO - Job 404: Subtask train_model_iterative
[2025-09-08T19:22:36.102+0000] {task_command.py:426} INFO - Running <TaskInstance: train_model_dag_batch_iterative_85000.train_model_iterative manual__2025-09-08T19:09:15.653145+00:00 [running]> on host 50a52b70bec0
[2025-09-08T19:22:36.496+0000] {taskinstance.py:2648} INFO - Exporting env vars: AIRFLOW_CTX_DAG_OWNER='airflow' AIRFLOW_CTX_DAG_ID='train_model_dag_batch_iterative_85000' AIRFLOW_CTX_TASK_ID='train_model_iterative' AIRFLOW_CTX_EXECUTION_DATE='2025-09-08T19:09:15.653145+00:00' AIRFLOW_CTX_TRY_NUMBER='2' AIRFLOW_CTX_DAG_RUN_ID='manual__2025-09-08T19:09:15.653145+00:00'
[2025-09-08T19:22:36.500+0000] {taskinstance.py:430} INFO - ::endgroup::
[2025-09-08T19:32:09.060+0000] {taskinstance.py:441} INFO - ::group::Post task execution logs
[2025-09-08T19:32:09.568+0000] {taskinstance.py:2905} ERROR - Task failed with exception
Traceback (most recent call last):
  File "/home/airflow/.local/lib/python3.8/site-packages/urllib3/connectionpool.py", line 715, in urlopen
    httplib_response = self._make_request(
  File "/home/airflow/.local/lib/python3.8/site-packages/urllib3/connectionpool.py", line 467, in _make_request
    six.raise_from(e, None)
  File "<string>", line 3, in raise_from
  File "/home/airflow/.local/lib/python3.8/site-packages/urllib3/connectionpool.py", line 462, in _make_request
    httplib_response = conn.getresponse()
  File "/usr/local/lib/python3.8/http/client.py", line 1348, in getresponse
    response.begin()
  File "/usr/local/lib/python3.8/http/client.py", line 316, in begin
    version, status, reason = self._read_status()
  File "/usr/local/lib/python3.8/http/client.py", line 285, in _read_status
    raise RemoteDisconnected("Remote end closed connection without"
http.client.RemoteDisconnected: Remote end closed connection without response

During handling of the above exception, another exception occurred:

Traceback (most recent call last):
  File "/home/airflow/.local/lib/python3.8/site-packages/requests/adapters.py", line 667, in send
    resp = conn.urlopen(
  File "/home/airflow/.local/lib/python3.8/site-packages/urllib3/connectionpool.py", line 799, in urlopen
    retries = retries.increment(
  File "/home/airflow/.local/lib/python3.8/site-packages/urllib3/util/retry.py", line 550, in increment
    raise six.reraise(type(error), error, _stacktrace)
  File "/home/airflow/.local/lib/python3.8/site-packages/urllib3/packages/six.py", line 769, in reraise
    raise value.with_traceback(tb)
  File "/home/airflow/.local/lib/python3.8/site-packages/urllib3/connectionpool.py", line 715, in urlopen
    httplib_response = self._make_request(
  File "/home/airflow/.local/lib/python3.8/site-packages/urllib3/connectionpool.py", line 467, in _make_request
    six.raise_from(e, None)
  File "<string>", line 3, in raise_from
  File "/home/airflow/.local/lib/python3.8/site-packages/urllib3/connectionpool.py", line 462, in _make_request
    httplib_response = conn.getresponse()
  File "/usr/local/lib/python3.8/http/client.py", line 1348, in getresponse
    response.begin()
  File "/usr/local/lib/python3.8/http/client.py", line 316, in begin
    version, status, reason = self._read_status()
  File "/usr/local/lib/python3.8/http/client.py", line 285, in _read_status
    raise RemoteDisconnected("Remote end closed connection without"
urllib3.exceptions.ProtocolError: ('Connection aborted.', RemoteDisconnected('Remote end closed connection without response'))

During handling of the above exception, another exception occurred:

Traceback (most recent call last):
  File "/home/airflow/.local/lib/python3.8/site-packages/airflow/models/taskinstance.py", line 465, in _execute_task
    result = _execute_callable(context=context, **execute_callable_kwargs)
  File "/home/airflow/.local/lib/python3.8/site-packages/airflow/models/taskinstance.py", line 432, in _execute_callable
    return execute_callable(context=context, **execute_callable_kwargs)
  File "/home/airflow/.local/lib/python3.8/site-packages/airflow/models/baseoperator.py", line 401, in wrapper
    return func(self, *args, **kwargs)
  File "/home/airflow/.local/lib/python3.8/site-packages/airflow/operators/python.py", line 235, in execute
    return_value = self.execute_callable()
  File "/home/airflow/.local/lib/python3.8/site-packages/airflow/operators/python.py", line 252, in execute_callable
    return self.python_callable(*self.op_args, **self.op_kwargs)
  File "/opt/airflow/dags/train_dag.py", line 95, in send_batches_to_train_api
    response = requests.post(train_url, headers=headers, data=json.dumps(payload), timeout=600)
  File "/home/airflow/.local/lib/python3.8/site-packages/requests/api.py", line 115, in post
    return request("post", url, data=data, json=json, **kwargs)
  File "/home/airflow/.local/lib/python3.8/site-packages/requests/api.py", line 59, in request
    return session.request(method=method, url=url, **kwargs)
  File "/home/airflow/.local/lib/python3.8/site-packages/requests/sessions.py", line 589, in request
    resp = self.send(prep, **send_kwargs)
  File "/home/airflow/.local/lib/python3.8/site-packages/requests/sessions.py", line 703, in send
    r = adapter.send(request, **kwargs)
  File "/home/airflow/.local/lib/python3.8/site-packages/requests/adapters.py", line 682, in send
    raise ConnectionError(err, request=request)
requests.exceptions.ConnectionError: ('Connection aborted.', RemoteDisconnected('Remote end closed connection without response'))
[2025-09-08T19:32:10.841+0000] {taskinstance.py:1206} INFO - Marking task as FAILED. dag_id=train_model_dag_batch_iterative_85000, task_id=train_model_iterative, run_id=manual__2025-09-08T19:09:15.653145+00:00, execution_date=20250908T190915, start_date=20250908T192235, end_date=20250908T193210
[2025-09-08T19:32:11.727+0000] {standard_task_runner.py:110} ERROR - Failed to execute job 404 for task train_model_iterative (('Connection aborted.', RemoteDisconnected('Remote end closed connection without response')); 7322)
[2025-09-08T19:32:11.909+0000] {local_task_job_runner.py:240} INFO - Task exited with return code 1
[2025-09-08T19:32:12.281+0000] {local_task_job_runner.py:222} INFO - ::endgroup::
