[2025-09-08T19:44:11.548+0000] {local_task_job_runner.py:120} INFO - ::group::Pre task execution logs
[2025-09-08T19:44:11.598+0000] {taskinstance.py:2076} INFO - Dependencies all met for dep_context=non-requeueable deps ti=<TaskInstance: train_model_dag_batch_iterative_85000.train_model_iterative manual__2025-09-08T19:35:56.253271+00:00 [queued]>
[2025-09-08T19:44:11.623+0000] {taskinstance.py:2076} INFO - Dependencies all met for dep_context=requeueable deps ti=<TaskInstance: train_model_dag_batch_iterative_85000.train_model_iterative manual__2025-09-08T19:35:56.253271+00:00 [queued]>
[2025-09-08T19:44:11.624+0000] {taskinstance.py:2306} INFO - Starting attempt 2 of 2
[2025-09-08T19:44:11.663+0000] {taskinstance.py:2330} INFO - Executing <Task(PythonOperator): train_model_iterative> on 2025-09-08 19:35:56.253271+00:00
[2025-09-08T19:44:11.689+0000] {standard_task_runner.py:63} INFO - Started process 8085 to run task
[2025-09-08T19:44:11.696+0000] {standard_task_runner.py:90} INFO - Running: ['airflow', 'tasks', 'run', 'train_model_dag_batch_iterative_85000', 'train_model_iterative', 'manual__2025-09-08T19:35:56.253271+00:00', '--job-id', '413', '--raw', '--subdir', 'DAGS_FOLDER/train_dag.py', '--cfg-path', '/tmp/tmpzqb70kwx']
[2025-09-08T19:44:11.705+0000] {standard_task_runner.py:91} INFO - Job 413: Subtask train_model_iterative
[2025-09-08T19:44:11.827+0000] {task_command.py:426} INFO - Running <TaskInstance: train_model_dag_batch_iterative_85000.train_model_iterative manual__2025-09-08T19:35:56.253271+00:00 [running]> on host 50a52b70bec0
[2025-09-08T19:44:12.139+0000] {taskinstance.py:2648} INFO - Exporting env vars: AIRFLOW_CTX_DAG_OWNER='airflow' AIRFLOW_CTX_DAG_ID='train_model_dag_batch_iterative_85000' AIRFLOW_CTX_TASK_ID='train_model_iterative' AIRFLOW_CTX_EXECUTION_DATE='2025-09-08T19:35:56.253271+00:00' AIRFLOW_CTX_TRY_NUMBER='2' AIRFLOW_CTX_DAG_RUN_ID='manual__2025-09-08T19:35:56.253271+00:00'
[2025-09-08T19:44:12.142+0000] {taskinstance.py:430} INFO - ::endgroup::
[2025-09-08T19:54:18.009+0000] {taskinstance.py:441} INFO - ::group::Post task execution logs
[2025-09-08T19:54:18.422+0000] {taskinstance.py:2905} ERROR - Task failed with exception
Traceback (most recent call last):
  File "/home/airflow/.local/lib/python3.8/site-packages/urllib3/connectionpool.py", line 467, in _make_request
    six.raise_from(e, None)
  File "<string>", line 3, in raise_from
  File "/home/airflow/.local/lib/python3.8/site-packages/urllib3/connectionpool.py", line 462, in _make_request
    httplib_response = conn.getresponse()
  File "/usr/local/lib/python3.8/http/client.py", line 1348, in getresponse
    response.begin()
  File "/usr/local/lib/python3.8/http/client.py", line 316, in begin
    version, status, reason = self._read_status()
  File "/usr/local/lib/python3.8/http/client.py", line 277, in _read_status
    line = str(self.fp.readline(_MAXLINE + 1), "iso-8859-1")
  File "/usr/local/lib/python3.8/socket.py", line 669, in readinto
    return self._sock.recv_into(b)
socket.timeout: timed out

During handling of the above exception, another exception occurred:

Traceback (most recent call last):
  File "/home/airflow/.local/lib/python3.8/site-packages/requests/adapters.py", line 667, in send
    resp = conn.urlopen(
  File "/home/airflow/.local/lib/python3.8/site-packages/urllib3/connectionpool.py", line 799, in urlopen
    retries = retries.increment(
  File "/home/airflow/.local/lib/python3.8/site-packages/urllib3/util/retry.py", line 550, in increment
    raise six.reraise(type(error), error, _stacktrace)
  File "/home/airflow/.local/lib/python3.8/site-packages/urllib3/packages/six.py", line 770, in reraise
    raise value
  File "/home/airflow/.local/lib/python3.8/site-packages/urllib3/connectionpool.py", line 715, in urlopen
    httplib_response = self._make_request(
  File "/home/airflow/.local/lib/python3.8/site-packages/urllib3/connectionpool.py", line 469, in _make_request
    self._raise_timeout(err=e, url=url, timeout_value=read_timeout)
  File "/home/airflow/.local/lib/python3.8/site-packages/urllib3/connectionpool.py", line 358, in _raise_timeout
    raise ReadTimeoutError(
urllib3.exceptions.ReadTimeoutError: HTTPConnectionPool(host='train-api', port=5002): Read timed out. (read timeout=600)

During handling of the above exception, another exception occurred:

Traceback (most recent call last):
  File "/home/airflow/.local/lib/python3.8/site-packages/airflow/models/taskinstance.py", line 465, in _execute_task
    result = _execute_callable(context=context, **execute_callable_kwargs)
  File "/home/airflow/.local/lib/python3.8/site-packages/airflow/models/taskinstance.py", line 432, in _execute_callable
    return execute_callable(context=context, **execute_callable_kwargs)
  File "/home/airflow/.local/lib/python3.8/site-packages/airflow/models/baseoperator.py", line 401, in wrapper
    return func(self, *args, **kwargs)
  File "/home/airflow/.local/lib/python3.8/site-packages/airflow/operators/python.py", line 235, in execute
    return_value = self.execute_callable()
  File "/home/airflow/.local/lib/python3.8/site-packages/airflow/operators/python.py", line 252, in execute_callable
    return self.python_callable(*self.op_args, **self.op_kwargs)
  File "/opt/airflow/dags/train_dag.py", line 95, in send_batches_to_train_api
    response = requests.post(train_url, headers=headers, data=json.dumps(payload), timeout=600)
  File "/home/airflow/.local/lib/python3.8/site-packages/requests/api.py", line 115, in post
    return request("post", url, data=data, json=json, **kwargs)
  File "/home/airflow/.local/lib/python3.8/site-packages/requests/api.py", line 59, in request
    return session.request(method=method, url=url, **kwargs)
  File "/home/airflow/.local/lib/python3.8/site-packages/requests/sessions.py", line 589, in request
    resp = self.send(prep, **send_kwargs)
  File "/home/airflow/.local/lib/python3.8/site-packages/requests/sessions.py", line 703, in send
    r = adapter.send(request, **kwargs)
  File "/home/airflow/.local/lib/python3.8/site-packages/requests/adapters.py", line 713, in send
    raise ReadTimeout(e, request=request)
requests.exceptions.ReadTimeout: HTTPConnectionPool(host='train-api', port=5002): Read timed out. (read timeout=600)
[2025-09-08T19:54:19.294+0000] {taskinstance.py:1206} INFO - Marking task as FAILED. dag_id=train_model_dag_batch_iterative_85000, task_id=train_model_iterative, run_id=manual__2025-09-08T19:35:56.253271+00:00, execution_date=20250908T193556, start_date=20250908T194411, end_date=20250908T195419
[2025-09-08T19:54:19.839+0000] {standard_task_runner.py:110} ERROR - Failed to execute job 413 for task train_model_iterative (HTTPConnectionPool(host='train-api', port=5002): Read timed out. (read timeout=600); 8085)
[2025-09-08T19:54:20.092+0000] {local_task_job_runner.py:240} INFO - Task exited with return code 1
[2025-09-08T19:54:20.624+0000] {taskinstance.py:3503} INFO - 0 downstream tasks scheduled from follow-on schedule check
[2025-09-08T19:54:20.663+0000] {local_task_job_runner.py:222} INFO - ::endgroup::
